<?xml version="1.0" ?>
<!-- =================================================================================== -->
<!-- |    This document was autogenerated by xacro from my_robot_integration.urdf.xacro | -->
<!-- |    EDITING THIS FILE BY HAND IS NOT RECOMMENDED                                 | -->
<!-- =================================================================================== -->
<!-- Name your robot here -->
<robot name="updated_assembly">
  <link name="chassis">
    <inertial>
      <origin rpy="0 0 0" xyz="-0.616773657514888 -4.34853353439648E-08 0.146342231101862"/>
      <mass value="41.5853551802886"/>
      <inertia ixx="0.779362029443521" ixy="5.13040313927605E-06" ixz="0.395543854550346" iyy="2.49517805123046" iyz="-2.04865621142101E-06" izz="2.66085738422244"/>
    </inertial>
    <visual>
      <origin rpy="0 0 0" xyz="0 0 0"/>
      <geometry>
        <mesh filename="package://updated_assembly/meshes/chassis.STL"/>
      </geometry>
      <material name="">
        <color rgba="0.792156862745098 0.819607843137255 0.933333333333333 1"/>
      </material>
    </visual>
    <collision>
      <origin rpy="0 0 0" xyz="0 0 0"/>
      <geometry>
        <mesh filename="package://updated_assembly/meshes/chassis.STL"/>
      </geometry>
    </collision>
  </link>
  <link name="right_stubble">
    <inertial>
      <origin rpy="0 0 0" xyz="0.000493625868364517 -0.00730515849096751 -0.0219698232437771"/>
      <mass value="0.0794074667477977"/>
      <inertia ixx="3.1138971614894E-05" ixy="7.32024407649854E-08" ixz="-1.75460715547232E-07" iyy="3.00605967383084E-05" iyz="2.59663931361191E-06" izz="2.66046329228299E-05"/>
    </inertial>
    <visual>
      <origin rpy="0 0 0" xyz="0 0 0"/>
      <geometry>
        <mesh filename="package://updated_assembly/meshes/right_stubble.STL"/>
      </geometry>
      <material name="">
        <color rgba="0.792156862745098 0.819607843137255 0.933333333333333 1"/>
      </material>
    </visual>
    <collision>
      <origin rpy="0 0 0" xyz="0 0 0"/>
      <geometry>
        <mesh filename="package://updated_assembly/meshes/right_stubble.STL"/>
      </geometry>
    </collision>
  </link>
  <joint name="right_stubbleJ" type="revolute">
    <origin rpy="0 0 0" xyz="-0.23495 -0.10795 0.14478"/>
    <parent link="chassis"/>
    <child link="right_stubble"/>
    <axis xyz="0 0 -1"/>
    <limit effort="10" lower="-0.34907" upper="0.34907" velocity="100"/>
  </joint>
  <link name="front_right_wheel">
    <inertial>
      <origin rpy="0 0 0" xyz="-6.63358257213531E-15 4.37150315946155E-15 0.0395540914856702"/>
      <mass value="2.27734930086204"/>
      <inertia ixx="0.00710492920653124" ixy="1.58753565960078E-15" ixz="-1.75678699018689E-15" iyy="0.00710492920653248" iyz="1.21772395875685E-15" izz="0.0119904910382331"/>
    </inertial>
    <visual>
      <origin rpy="0 0 0" xyz="0 0 0"/>
      <geometry>
        <mesh filename="package://updated_assembly/meshes/front_right_wheel.STL"/>
      </geometry>
      <material name="">
        <color rgba="0.792156862745098 0.819607843137255 0.933333333333333 1"/>
      </material>
    </visual>
    <collision>
      <origin rpy="0 0 0" xyz="0 0 0"/>
      <geometry>
        <mesh filename="package://updated_assembly/meshes/front_right_wheel.STL"/>
      </geometry>
    </collision>
  </link>
  <joint name="front_right_wheelJ" type="continuous">
    <origin rpy="1.5708 0 -3.0741" xyz="0.0077059 -0.11404 -0.04064"/>
    <parent link="right_stubble"/>
    <child link="front_right_wheel"/>
    <axis xyz="0 0 1"/>
  </joint>
  <link name="left_stubble">
    <inertial>
      <origin rpy="0 0 0" xyz="0 0.00732181719766843 -0.0219698232437771"/>
      <mass value="0.0794074667477977"/>
      <inertia ixx="3.11439180672446E-05" ixy="-5.39983503874616E-21" ixz="-5.02925812432241E-21" iyy="3.00556502859579E-05" iyz="-2.60256069817695E-06" izz="2.66046329228299E-05"/>
    </inertial>
    <visual>
      <origin rpy="0 0 0" xyz="0 0 0"/>
      <geometry>
        <mesh filename="package://updated_assembly/meshes/left_stubble.STL"/>
      </geometry>
      <material name="">
        <color rgba="0.792156862745098 0.819607843137255 0.933333333333333 1"/>
      </material>
    </visual>
    <collision>
      <origin rpy="0 0 0" xyz="0 0 0"/>
      <geometry>
        <mesh filename="package://updated_assembly/meshes/left_stubble.STL"/>
      </geometry>
    </collision>
  </link>
  <joint name="left_stubbleJ" type="revolute">
    <origin rpy="0 0 0.042278" xyz="-0.23495 0.10795 0.14478"/>
    <parent link="chassis"/>
    <child link="left_stubble"/>
    <axis xyz="0 0 -1"/>
    <limit effort="10" lower="-0.34907" upper="0.34907" velocity="100"/>
  </joint>
  <link name="front_left_wheel">
    <inertial>
      <origin rpy="0 0 0" xyz="-7.7715611723761E-15 2.67841304690819E-15 0.0395540914856701"/>
      <mass value="2.27734930086202"/>
      <inertia ixx="0.00710492920653056" ixy="1.08618435030828E-15" ixz="-2.06247779271918E-15" iyy="0.00710492920653318" iyz="7.53683956364923E-16" izz="0.0119904910382328"/>
    </inertial>
    <visual>
      <origin rpy="0 0 0" xyz="0 0 0"/>
      <geometry>
        <mesh filename="package://updated_assembly/meshes/front_left_wheel.STL"/>
      </geometry>
      <material name="">
        <color rgba="0.792156862745098 0.819607843137255 0.933333333333333 1"/>
      </material>
    </visual>
    <collision>
      <origin rpy="0 0 0" xyz="0 0 0"/>
      <geometry>
        <mesh filename="package://updated_assembly/meshes/front_left_wheel.STL"/>
      </geometry>
    </collision>
  </link>
  <joint name="front_left_wheelJ" type="continuous">
    <origin rpy="1.5708 0 0" xyz="0 0.1143 -0.04064"/>
    <parent link="left_stubble"/>
    <child link="front_left_wheel"/>
    <axis xyz="0 0 1"/>
  </joint>
  <link name="rear_right_wheel">
    <inertial>
      <origin rpy="0 0 0" xyz="4.32986979603811E-15 -6.98052726733067E-15 0.0395540914856703"/>
      <mass value="2.27734930086199"/>
      <inertia ixx="0.00710492920653265" ixy="1.50573010392001E-15" ixz="1.13646128196408E-15" iyy="0.00710492920653107" iyz="-1.89862675756808E-15" izz="0.0119904910382325"/>
    </inertial>
    <visual>
      <origin rpy="0 0 0" xyz="0 0 0"/>
      <geometry>
        <mesh filename="package://updated_assembly/meshes/rear_right_wheel.STL"/>
      </geometry>
      <material name="">
        <color rgba="0.792156862745098 0.819607843137255 0.933333333333333 1"/>
      </material>
    </visual>
    <collision>
      <origin rpy="0 0 0" xyz="0 0 0"/>
      <geometry>
        <mesh filename="package://updated_assembly/meshes/rear_right_wheel.STL"/>
      </geometry>
    </collision>
  </link>
  <joint name="rear_right_wheelJ" type="continuous">
    <origin rpy="1.5708 0 3.1416" xyz="-0.8636 -0.23495 0.1016"/>
    <parent link="chassis"/>
    <child link="rear_right_wheel"/>
    <axis xyz="0 0 1"/>
  </joint>
  <link name="rear_left_wheel">
    <inertial>
      <origin rpy="0 0 0" xyz="-1.11022302462516E-16 8.22952817003397E-15 0.0395540914856703"/>
      <mass value="2.27734930086199"/>
      <inertia ixx="0.00710492920653356" ixy="-3.832285813084E-17" ixz="3.23743942117421E-17" iyy="0.00710492920653015" iyz="2.21267793842341E-15" izz="0.0119904910382325"/>
    </inertial>
    <visual>
      <origin rpy="0 0 0" xyz="0 0 0"/>
      <geometry>
        <mesh filename="package://updated_assembly/meshes/rear_left_wheel.STL"/>
      </geometry>
      <material name="">
        <color rgba="0.792156862745098 0.819607843137255 0.933333333333333 1"/>
      </material>
    </visual>
    <collision>
      <origin rpy="0 0 0" xyz="0 0 0"/>
      <geometry>
        <mesh filename="package://updated_assembly/meshes/rear_left_wheel.STL"/>
      </geometry>
    </collision>
  </link>
  <joint name="rear_left_wheelJ" type="continuous">
    <origin rpy="1.5708 0 0" xyz="-0.8636 0.23495 0.1016"/>
    <parent link="chassis"/>
    <child link="rear_left_wheel"/>
    <axis xyz="0 0 -1"/>
  </joint>
  <link name="dummy_link">
  </link>
  <joint name="dummy_joint" type="fixed">
    <parent link="dummy_link"/>
    <child link="chassis"/>
  </joint>
  <transmission name="trans_right_stubble">
    <type>transmission_interface/SimpleTransmission</type>
    <joint name="right_stubbleJ">
      <hardwareInterface>hardware_interface/EffortJointInterface</hardwareInterface>
    </joint>
    <actuator name="right_stubbleJ_motor">
      <mechanicalReduction>1</mechanicalReduction>
      <hardwareInterface>hardware_interface/EffortJointInterface</hardwareInterface>
    </actuator>
  </transmission>
  <transmission name="trans_left_stubble">
    <type>transmission_interface/SimpleTransmission</type>
    <joint name="left_stubbleJ">
      <hardwareInterface>hardware_interface/EffortJointInterface</hardwareInterface>
    </joint>
    <actuator name="left_stubbleJ_motor">
      <mechanicalReduction>1</mechanicalReduction>
      <hardwareInterface>hardware_interface/EffortJointInterface</hardwareInterface>
    </actuator>
  </transmission>
  <transmission name="trans_front_left_wheel">
    <type>transmission_interface/SimpleTransmission</type>
    <joint name="front_left_wheelJ">
      <hardwareInterface>hardware_interface/EffortJointInterface</hardwareInterface>
    </joint>
    <actuator name="front_left_wheel_motor">
      <mechanicalReduction>1</mechanicalReduction>
      <hardwareInterface>hardware_interface/EffortJointInterface</hardwareInterface>
    </actuator>
  </transmission>
  <transmission name="trans_front_right_wheel">
    <type>transmission_interface/SimpleTransmission</type>
    <joint name="front_right_wheelJ">
      <hardwareInterface>hardware_interface/EffortJointInterface</hardwareInterface>
    </joint>
    <actuator name="front_right_wheel_motor">
      <mechanicalReduction>1</mechanicalReduction>
      <hardwareInterface>hardware_interface/EffortJointInterface</hardwareInterface>
    </actuator>
  </transmission>
  <transmission name="trans_rear_right_wheel">
    <type>transmission_interface/SimpleTransmission</type>
    <joint name="rear_right_wheelJ">
      <hardwareInterface>hardware_interface/VelocityJointInterface</hardwareInterface>
    </joint>
    <actuator name="rear_right_wheel_motor">
      <mechanicalReduction>1</mechanicalReduction>
      <hardwareInterface>hardware_interface/VelocityJointInterface</hardwareInterface>
    </actuator>
  </transmission>
  <transmission name="trans_rear_left_wheel">
    <type>transmission_interface/SimpleTransmission</type>
    <joint name="rear_left_wheelJ">
      <hardwareInterface>hardware_interface/VelocityJointInterface</hardwareInterface>
    </joint>
    <actuator name="rear_left_wheel_motor">
      <mechanicalReduction>1</mechanicalReduction>
      <hardwareInterface>hardware_interface/VelocityJointInterface</hardwareInterface>
    </actuator>
  </transmission>
  <link name="base_laser">
    <inertial>
      <origin rpy="0 0 0" xyz="-0.00029774 0.0066667 0.00013047"/>
      <mass value="0.15717"/>
      <inertia ixx="6.7885E-05" ixy="-1.3987E-07" ixz="-8.1554E-07" iyy="0.00013173" iyz="-9.0932E-08" izz="7.1972E-05"/>
    </inertial>
    <visual>
      <origin rpy="0 0 0" xyz="0 0 0"/>
      <geometry>
        <mesh filename="package://updated_assembly/meshes/ydlidar.dae"/>
      </geometry>
      <material name="">
        <color rgba="0.64706 0.61961 0.58824 1"/>
      </material>
    </visual>
    <collision>
      <origin rpy="0 0 0" xyz="0 0 0"/>
      <geometry>
        <mesh filename="package://updated_assembly/meshes/ydlidar.dae"/>
      </geometry>
    </collision>
  </link>
  <link name="laser_frame">
    <inertial>
      <origin rpy="0 0 0" xyz="-0.00036659 0.00064155 -0.00027052"/>
      <mass value="0.25482"/>
      <inertia ixx="8.9194E-05" ixy="1.8116E-07" ixz="3.6435E-08" iyy="0.00018279" iyz="2.423E-07" izz="0.00011103"/>
    </inertial>
    <!--visual>
      <origin
        xyz="0 0 0"
        rpy="0 0 0" />
      <geometry>
        <mesh
          filename="package://updated_assembly/meshes/ydlidar.dae" />
      </geometry>
      <material
        name="">
        <color
          rgba="0.64706 0.61961 0.58824 1" />
      </material>
    </visual-->
    <!--collision>
      <origin
        xyz="0 0 0"
        rpy="0 0 0" />
      <geometry>
        <mesh
          filename="package://updated_assembly/meshes/ydlidar.dae" />
      </geometry>
    </collision-->
  </link>
  <joint name="laser_joint" type="fixed">
    <origin rpy="0 0 0" xyz="0 0 0.03172"/>
    <parent link="base_laser"/>
    <child link="laser_frame"/>
    <axis xyz="0 0 0"/>
  </joint>
  <gazebo reference="base_laser">
    <sensor name="laser" type="ray">
      <pose> 0 0 0 0 0 0 </pose>
      <visualise>true</visualise>
      <update_rate>40</update_rate>
      <ray>
        <scan>
          <horizontal>
            <samples>720</samples>
            <resolution>1</resolution>
            <min_angle>-1.570796</min_angle>
            <max_angle>1.570796</max_angle>
          </horizontal>
        </scan>
        <range>
          <min>0.10</min>
          <max>30.0</max>
          <resolution>0.01</resolution>
        </range>
        <noise>
          <type>gaussian</type>
          <mean>0.0</mean>
          <stddev>0.01</stddev>
        </noise>
      </ray>
      <plugin filename="libgazebo_ros_laser.so" name="gazebo_ros_head_hokuyo_controller">
        <!--  Use topic name as /my_robot/scan  -->
        <topicName>/updated_assembly/scan</topicName>
        <frameName>laser_frame</frameName>
      </plugin>
    </sensor>
  </gazebo>
  <gazebo>
    <plugin filename="libgazebo_ros_control.so" name="gazebo_ros_control">
      <robotNamespace>/updated_assembly</robotNamespace>
      <robotSimType>gazebo_ros_control/DefaultRobotHWSim</robotSimType>
      <legacyModeNS>true</legacyModeNS>
    </plugin>
  </gazebo>
  <joint name="robot_sensor" type="fixed">
    <parent link="chassis"/>
    <child link="base_laser"/>
    <origin rpy="0 0 0" xyz="0 0 0.1"/>
  </joint>
  <!-- Create a joint between your robot and sensor -->
</robot>
